Microsoft Windows [Version 10.0.18363.1198]
(c) 2019 Microsoft Corporation. All rights reserved.

C:\Users\aneeta>cd Documents

C:\Users\aneeta\Documents>spect_env\scripts\activate

(spect_env) C:\Users\aneeta\Documents>django-admin startproject SRS

(spect_env) C:\Users\aneeta\Documents>cd SRS

(spect_env) C:\Users\aneeta\Documents\SRS>python manage.py runserver
Watching for file changes with StatReloader
Performing system checks...

System check identified no issues (0 silenced).

You have 18 unapplied migration(s). Your project may not work properly until you apply the migrations for app(s): admin, auth, contenttypes, sessions.
Run 'python manage.py migrate' to apply them.
May 03, 2021 - 21:44:02
Django version 3.2, using settings 'SRS.settings'
Starting development server at http://127.0.0.1:8000/
Quit the server with CTRL-BREAK.

(spect_env) C:\Users\aneeta\Documents\SRS>python manage.py runserver
Watching for file changes with StatReloader
Performing system checks...

System check identified no issues (0 silenced).

You have 18 unapplied migration(s). Your project may not work properly until you apply the migrations for app(s): admin, auth, contenttypes, sessions.
Run 'python manage.py migrate' to apply them.
May 03, 2021 - 21:44:25
Django version 3.2, using settings 'SRS.settings'
Starting development server at http://127.0.0.1:8000/
Quit the server with CTRL-BREAK.
Internal Server Error: /admin/
Traceback (most recent call last):
  File "C:\Users\aneeta\Documents\spect_env\lib\site-packages\django\contrib\sessions\backends\base.py", line 233, in _get_session
    return self._session_cache
AttributeError: 'SessionStore' object has no attribute '_session_cache'

During handling of the above exception, another exception occurred:

Traceback (most recent call last):
  File "C:\Users\aneeta\Documents\spect_env\lib\site-packages\django\db\backends\utils.py", line 84, in _execute
    return self.cursor.execute(sql, params)
  File "C:\Users\aneeta\Documents\spect_env\lib\site-packages\django\db\backends\sqlite3\base.py", line 423, in execute
    return Database.Cursor.execute(self, query, params)
sqlite3.OperationalError: no such table: django_session

The above exception was the direct cause of the following exception:

Traceback (most recent call last):
  File "C:\Users\aneeta\Documents\spect_env\lib\site-packages\django\core\handlers\exception.py", line 47, in inner
    response = get_response(request)
  File "C:\Users\aneeta\Documents\spect_env\lib\site-packages\django\core\handlers\base.py", line 181, in _get_response
    response = wrapped_callback(request, *callback_args, **callback_kwargs)
  File "C:\Users\aneeta\Documents\spect_env\lib\site-packages\django\contrib\admin\sites.py", line 250, in wrapper
    return self.admin_view(view, cacheable)(*args, **kwargs)
  File "C:\Users\aneeta\Documents\spect_env\lib\site-packages\django\utils\decorators.py", line 130, in _wrapped_view
    response = view_func(request, *args, **kwargs)
  File "C:\Users\aneeta\Documents\spect_env\lib\site-packages\django\views\decorators\cache.py", line 44, in _wrapped_view_func
    response = view_func(request, *args, **kwargs)
  File "C:\Users\aneeta\Documents\spect_env\lib\site-packages\django\contrib\admin\sites.py", line 221, in inner
    if not self.has_permission(request):
  File "C:\Users\aneeta\Documents\spect_env\lib\site-packages\django\contrib\admin\sites.py", line 195, in has_permission
    return request.user.is_active and request.user.is_staff
  File "C:\Users\aneeta\Documents\spect_env\lib\site-packages\django\utils\functional.py", line 246, in inner
    self._setup()
  File "C:\Users\aneeta\Documents\spect_env\lib\site-packages\django\utils\functional.py", line 382, in _setup
    self._wrapped = self._setupfunc()
  File "C:\Users\aneeta\Documents\spect_env\lib\site-packages\django\contrib\auth\middleware.py", line 23, in <lambda>
    request.user = SimpleLazyObject(lambda: get_user(request))
  File "C:\Users\aneeta\Documents\spect_env\lib\site-packages\django\contrib\auth\middleware.py", line 11, in get_user
    request._cached_user = auth.get_user(request)
  File "C:\Users\aneeta\Documents\spect_env\lib\site-packages\django\contrib\auth\__init__.py", line 177, in get_user
    user_id = _get_user_session_key(request)
  File "C:\Users\aneeta\Documents\spect_env\lib\site-packages\django\contrib\auth\__init__.py", line 60, in _get_user_session_key
    return get_user_model()._meta.pk.to_python(request.session[SESSION_KEY])
  File "C:\Users\aneeta\Documents\spect_env\lib\site-packages\django\contrib\sessions\backends\base.py", line 65, in __getitem__
    return self._session[key]
  File "C:\Users\aneeta\Documents\spect_env\lib\site-packages\django\contrib\sessions\backends\base.py", line 238, in _get_session
    self._session_cache = self.load()
  File "C:\Users\aneeta\Documents\spect_env\lib\site-packages\django\contrib\sessions\backends\db.py", line 43, in load
    s = self._get_session_from_db()
  File "C:\Users\aneeta\Documents\spect_env\lib\site-packages\django\contrib\sessions\backends\db.py", line 32, in _get_session_from_db
    return self.model.objects.get(
  File "C:\Users\aneeta\Documents\spect_env\lib\site-packages\django\db\models\manager.py", line 85, in manager_method
    return getattr(self.get_queryset(), name)(*args, **kwargs)
  File "C:\Users\aneeta\Documents\spect_env\lib\site-packages\django\db\models\query.py", line 431, in get
    num = len(clone)
  File "C:\Users\aneeta\Documents\spect_env\lib\site-packages\django\db\models\query.py", line 262, in __len__
    self._fetch_all()
  File "C:\Users\aneeta\Documents\spect_env\lib\site-packages\django\db\models\query.py", line 1324, in _fetch_all
    self._result_cache = list(self._iterable_class(self))
  File "C:\Users\aneeta\Documents\spect_env\lib\site-packages\django\db\models\query.py", line 51, in __iter__
    results = compiler.execute_sql(chunked_fetch=self.chunked_fetch, chunk_size=self.chunk_size)
  File "C:\Users\aneeta\Documents\spect_env\lib\site-packages\django\db\models\sql\compiler.py", line 1169, in execute_sql
    cursor.execute(sql, params)
  File "C:\Users\aneeta\Documents\spect_env\lib\site-packages\django\db\backends\utils.py", line 98, in execute
    return super().execute(sql, params)
  File "C:\Users\aneeta\Documents\spect_env\lib\site-packages\django\db\backends\utils.py", line 66, in execute
    return self._execute_with_wrappers(sql, params, many=False, executor=self._execute)
  File "C:\Users\aneeta\Documents\spect_env\lib\site-packages\django\db\backends\utils.py", line 75, in _execute_with_wrappers
    return executor(sql, params, many, context)
  File "C:\Users\aneeta\Documents\spect_env\lib\site-packages\django\db\backends\utils.py", line 84, in _execute
    return self.cursor.execute(sql, params)
  File "C:\Users\aneeta\Documents\spect_env\lib\site-packages\django\db\utils.py", line 90, in __exit__
    raise dj_exc_value.with_traceback(traceback) from exc_value
  File "C:\Users\aneeta\Documents\spect_env\lib\site-packages\django\db\backends\utils.py", line 84, in _execute
    return self.cursor.execute(sql, params)
  File "C:\Users\aneeta\Documents\spect_env\lib\site-packages\django\db\backends\sqlite3\base.py", line 423, in execute
    return Database.Cursor.execute(self, query, params)
django.db.utils.OperationalError: no such table: django_session
[03/May/2021 21:44:44] "GET /admin/ HTTP/1.1" 500 195511
Not Found: /favicon.ico
[03/May/2021 21:44:48] "GET /favicon.ico HTTP/1.1" 404 1992
Internal Server Error: /admin/
Traceback (most recent call last):
  File "C:\Users\aneeta\Documents\spect_env\lib\site-packages\django\contrib\sessions\backends\base.py", line 233, in _get_session
    return self._session_cache
AttributeError: 'SessionStore' object has no attribute '_session_cache'

During handling of the above exception, another exception occurred:

Traceback (most recent call last):
  File "C:\Users\aneeta\Documents\spect_env\lib\site-packages\django\db\backends\utils.py", line 84, in _execute
    return self.cursor.execute(sql, params)
  File "C:\Users\aneeta\Documents\spect_env\lib\site-packages\django\db\backends\sqlite3\base.py", line 423, in execute
    return Database.Cursor.execute(self, query, params)
sqlite3.OperationalError: no such table: django_session

The above exception was the direct cause of the following exception:

Traceback (most recent call last):
  File "C:\Users\aneeta\Documents\spect_env\lib\site-packages\django\core\handlers\exception.py", line 47, in inner
    response = get_response(request)
  File "C:\Users\aneeta\Documents\spect_env\lib\site-packages\django\core\handlers\base.py", line 181, in _get_response
    response = wrapped_callback(request, *callback_args, **callback_kwargs)
  File "C:\Users\aneeta\Documents\spect_env\lib\site-packages\django\contrib\admin\sites.py", line 250, in wrapper
    return self.admin_view(view, cacheable)(*args, **kwargs)
  File "C:\Users\aneeta\Documents\spect_env\lib\site-packages\django\utils\decorators.py", line 130, in _wrapped_view
    response = view_func(request, *args, **kwargs)
  File "C:\Users\aneeta\Documents\spect_env\lib\site-packages\django\views\decorators\cache.py", line 44, in _wrapped_view_func
    response = view_func(request, *args, **kwargs)
  File "C:\Users\aneeta\Documents\spect_env\lib\site-packages\django\contrib\admin\sites.py", line 221, in inner
    if not self.has_permission(request):
  File "C:\Users\aneeta\Documents\spect_env\lib\site-packages\django\contrib\admin\sites.py", line 195, in has_permission
    return request.user.is_active and request.user.is_staff
  File "C:\Users\aneeta\Documents\spect_env\lib\site-packages\django\utils\functional.py", line 246, in inner
    self._setup()
  File "C:\Users\aneeta\Documents\spect_env\lib\site-packages\django\utils\functional.py", line 382, in _setup
    self._wrapped = self._setupfunc()
  File "C:\Users\aneeta\Documents\spect_env\lib\site-packages\django\contrib\auth\middleware.py", line 23, in <lambda>
    request.user = SimpleLazyObject(lambda: get_user(request))
  File "C:\Users\aneeta\Documents\spect_env\lib\site-packages\django\contrib\auth\middleware.py", line 11, in get_user
    request._cached_user = auth.get_user(request)
  File "C:\Users\aneeta\Documents\spect_env\lib\site-packages\django\contrib\auth\__init__.py", line 177, in get_user
    user_id = _get_user_session_key(request)
  File "C:\Users\aneeta\Documents\spect_env\lib\site-packages\django\contrib\auth\__init__.py", line 60, in _get_user_session_key
    return get_user_model()._meta.pk.to_python(request.session[SESSION_KEY])
  File "C:\Users\aneeta\Documents\spect_env\lib\site-packages\django\contrib\sessions\backends\base.py", line 65, in __getitem__
    return self._session[key]
  File "C:\Users\aneeta\Documents\spect_env\lib\site-packages\django\contrib\sessions\backends\base.py", line 238, in _get_session
    self._session_cache = self.load()
  File "C:\Users\aneeta\Documents\spect_env\lib\site-packages\django\contrib\sessions\backends\db.py", line 43, in load
    s = self._get_session_from_db()
  File "C:\Users\aneeta\Documents\spect_env\lib\site-packages\django\contrib\sessions\backends\db.py", line 32, in _get_session_from_db
    return self.model.objects.get(
  File "C:\Users\aneeta\Documents\spect_env\lib\site-packages\django\db\models\manager.py", line 85, in manager_method
    return getattr(self.get_queryset(), name)(*args, **kwargs)
  File "C:\Users\aneeta\Documents\spect_env\lib\site-packages\django\db\models\query.py", line 431, in get
    num = len(clone)
  File "C:\Users\aneeta\Documents\spect_env\lib\site-packages\django\db\models\query.py", line 262, in __len__
    self._fetch_all()
  File "C:\Users\aneeta\Documents\spect_env\lib\site-packages\django\db\models\query.py", line 1324, in _fetch_all
    self._result_cache = list(self._iterable_class(self))
  File "C:\Users\aneeta\Documents\spect_env\lib\site-packages\django\db\models\query.py", line 51, in __iter__
    results = compiler.execute_sql(chunked_fetch=self.chunked_fetch, chunk_size=self.chunk_size)
  File "C:\Users\aneeta\Documents\spect_env\lib\site-packages\django\db\models\sql\compiler.py", line 1169, in execute_sql
    cursor.execute(sql, params)
  File "C:\Users\aneeta\Documents\spect_env\lib\site-packages\django\db\backends\utils.py", line 98, in execute
    return super().execute(sql, params)
  File "C:\Users\aneeta\Documents\spect_env\lib\site-packages\django\db\backends\utils.py", line 66, in execute
    return self._execute_with_wrappers(sql, params, many=False, executor=self._execute)
  File "C:\Users\aneeta\Documents\spect_env\lib\site-packages\django\db\backends\utils.py", line 75, in _execute_with_wrappers
    return executor(sql, params, many, context)
  File "C:\Users\aneeta\Documents\spect_env\lib\site-packages\django\db\backends\utils.py", line 84, in _execute
    return self.cursor.execute(sql, params)
  File "C:\Users\aneeta\Documents\spect_env\lib\site-packages\django\db\utils.py", line 90, in __exit__
    raise dj_exc_value.with_traceback(traceback) from exc_value
  File "C:\Users\aneeta\Documents\spect_env\lib\site-packages\django\db\backends\utils.py", line 84, in _execute
    return self.cursor.execute(sql, params)
  File "C:\Users\aneeta\Documents\spect_env\lib\site-packages\django\db\backends\sqlite3\base.py", line 423, in execute
    return Database.Cursor.execute(self, query, params)
django.db.utils.OperationalError: no such table: django_session
[03/May/2021 21:45:03] "GET /admin/ HTTP/1.1" 500 195377
[03/May/2021 21:45:21] "GET / HTTP/1.1" 200 10697
[03/May/2021 21:45:22] "GET /static/admin/css/fonts.css HTTP/1.1" 304 0
[03/May/2021 21:45:22] "GET /static/admin/fonts/Roboto-Regular-webfont.woff HTTP/1.1" 304 0
[03/May/2021 21:45:22] "GET /static/admin/fonts/Roboto-Bold-webfont.woff HTTP/1.1" 304 0
[03/May/2021 21:45:22] "GET /static/admin/fonts/Roboto-Light-webfont.woff HTTP/1.1" 304 0

(spect_env) C:\Users\aneeta\Documents\SRS>python manage.py migrate
Operations to perform:
  Apply all migrations: admin, auth, contenttypes, sessions
Running migrations:
  Applying contenttypes.0001_initial... OK
  Applying auth.0001_initial... OK
  Applying admin.0001_initial... OK
  Applying admin.0002_logentry_remove_auto_add... OK
  Applying admin.0003_logentry_add_action_flag_choices... OK
  Applying contenttypes.0002_remove_content_type_name... OK
  Applying auth.0002_alter_permission_name_max_length... OK
  Applying auth.0003_alter_user_email_max_length... OK
  Applying auth.0004_alter_user_username_opts... OK
  Applying auth.0005_alter_user_last_login_null... OK
  Applying auth.0006_require_contenttypes_0002... OK
  Applying auth.0007_alter_validators_add_error_messages... OK
  Applying auth.0008_alter_user_username_max_length... OK
  Applying auth.0009_alter_user_last_name_max_length... OK
  Applying auth.0010_alter_group_name_max_length... OK
  Applying auth.0011_update_proxy_permissions... OK
  Applying auth.0012_alter_user_first_name_max_length... OK
  Applying sessions.0001_initial... OK

(spect_env) C:\Users\aneeta\Documents\SRS>python manage.py runserver
Watching for file changes with StatReloader
Performing system checks...

System check identified no issues (0 silenced).
May 03, 2021 - 21:46:22
Django version 3.2, using settings 'SRS.settings'
Starting development server at http://127.0.0.1:8000/
Quit the server with CTRL-BREAK.
[03/May/2021 21:46:44] "GET /admin/ HTTP/1.1" 302 0
[03/May/2021 21:46:44] "GET /admin/login/?next=/admin/ HTTP/1.1" 200 2214
[03/May/2021 21:46:45] "GET /static/admin/css/base.css HTTP/1.1" 304 0
[03/May/2021 21:46:45] "GET /static/admin/css/login.css HTTP/1.1" 304 0
[03/May/2021 21:46:45] "GET /static/admin/css/responsive.css HTTP/1.1" 304 0
[03/May/2021 21:46:45] "GET /static/admin/css/nav_sidebar.css HTTP/1.1" 304 0
[03/May/2021 21:46:45] "GET /static/admin/js/nav_sidebar.js HTTP/1.1" 304 0

(spect_env) C:\Users\aneeta\Documents\SRS>python manage.py createsuperuser
Username (leave blank to use 'aneeta'): srs
Email address:
Password:
Password (again):
This password is too short. It must contain at least 8 characters.
Bypass password validation and create user anyway? [y/N]: n
Password:
Password (again):
Error: Blank passwords aren't allowed.
Password:
Password (again):
Superuser created successfully.

(spect_env) C:\Users\aneeta\Documents\SRS>python manage.py runserver
Watching for file changes with StatReloader
Performing system checks...

System check identified no issues (0 silenced).
May 03, 2021 - 21:51:26
Django version 3.2, using settings 'SRS.settings'
Starting development server at http://127.0.0.1:8000/
Quit the server with CTRL-BREAK.
[03/May/2021 21:51:49] "GET /admin/ HTTP/1.1" 302 0
[03/May/2021 21:51:49] "GET /admin/login/?next=/admin/ HTTP/1.1" 200 2214
[03/May/2021 21:51:52] "GET /admin/ HTTP/1.1" 302 0
[03/May/2021 21:51:52] "GET /admin/login/?next=/admin/ HTTP/1.1" 200 2214
[03/May/2021 21:52:11] "POST /admin/login/?next=/admin/ HTTP/1.1" 200 2373
[03/May/2021 21:52:37] "POST /admin/login/?next=/admin/ HTTP/1.1" 302 0
[03/May/2021 21:52:37] "GET /admin/ HTTP/1.1" 200 3324
[03/May/2021 21:52:37] "GET /static/admin/css/dashboard.css HTTP/1.1" 304 0
[03/May/2021 21:52:37] "GET /static/admin/img/icon-changelink.svg HTTP/1.1" 304 0
[03/May/2021 21:52:37] "GET /static/admin/img/icon-addlink.svg HTTP/1.1" 304 0
[03/May/2021 21:52:50] "GET /admin/auth/user/ HTTP/1.1" 200 7822
[03/May/2021 21:52:50] "GET /static/admin/js/jquery.init.js HTTP/1.1" 304 0
[03/May/2021 21:52:50] "GET /static/admin/css/changelists.css HTTP/1.1" 304 0
[03/May/2021 21:52:50] "GET /static/admin/js/vendor/xregexp/xregexp.js HTTP/1.1" 304 0
[03/May/2021 21:52:50] "GET /static/admin/js/core.js HTTP/1.1" 304 0
[03/May/2021 21:52:50] "GET /static/admin/js/actions.js HTTP/1.1" 304 0
[03/May/2021 21:52:50] "GET /static/admin/js/urlify.js HTTP/1.1" 304 0
[03/May/2021 21:52:50] "GET /static/admin/js/admin/RelatedObjectLookups.js HTTP/1.1" 304 0
[03/May/2021 21:52:50] "GET /admin/jsi18n/ HTTP/1.1" 200 3195
[03/May/2021 21:52:50] "GET /static/admin/js/prepopulate.js HTTP/1.1" 304 0
[03/May/2021 21:52:50] "GET /static/admin/js/vendor/jquery/jquery.js HTTP/1.1" 304 0
[03/May/2021 21:52:50] "GET /static/admin/img/search.svg HTTP/1.1" 304 0
[03/May/2021 21:52:51] "GET /static/admin/img/icon-yes.svg HTTP/1.1" 304 0
[03/May/2021 21:52:51] "GET /static/admin/img/tooltag-add.svg HTTP/1.1" 304 0
[03/May/2021 21:52:51] "GET /static/admin/img/sorting-icons.svg HTTP/1.1" 304 0
[03/May/2021 21:52:54] "GET /admin/auth/user/1/change/ HTTP/1.1" 200 15036
[03/May/2021 21:52:54] "GET /static/admin/css/forms.css HTTP/1.1" 304 0
[03/May/2021 21:52:54] "GET /static/admin/js/admin/DateTimeShortcuts.js HTTP/1.1" 304 0
[03/May/2021 21:52:54] "GET /static/admin/js/calendar.js HTTP/1.1" 304 0
[03/May/2021 21:52:54] "GET /admin/jsi18n/ HTTP/1.1" 200 3195
[03/May/2021 21:52:54] "GET /static/admin/js/SelectBox.js HTTP/1.1" 304 0
[03/May/2021 21:52:54] "GET /static/admin/js/SelectFilter2.js HTTP/1.1" 304 0
[03/May/2021 21:52:55] "GET /static/admin/css/widgets.css HTTP/1.1" 304 0
[03/May/2021 21:52:55] "GET /static/admin/js/prepopulate_init.js HTTP/1.1" 304 0
[03/May/2021 21:52:55] "GET /static/admin/js/change_form.js HTTP/1.1" 304 0
[03/May/2021 21:52:55] "GET /static/admin/img/icon-clock.svg HTTP/1.1" 304 0
[03/May/2021 21:52:55] "GET /static/admin/img/icon-calendar.svg HTTP/1.1" 304 0
[03/May/2021 21:52:55] "GET /static/admin/img/selector-icons.svg HTTP/1.1" 304 0

(spect_env) C:\Users\aneeta\Documents\SRS>python manage.py startapp general

(spect_env) C:\Users\aneeta\Documents\SRS>



















