Microsoft Windows [Version 10.0.18363.1198]
(c) 2019 Microsoft Corporation. All rights reserved.

C:\Users\aneeta>cd Documents

C:\Users\aneeta\Documents>spect_env\scripts\activate

(spect_env) C:\Users\aneeta\Documents>cd eshop

(spect_env) C:\Users\aneeta\Documents\eshop>python manage.py runserver
Watching for file changes with StatReloader
Performing system checks...

System check identified no issues (0 silenced).
May 06, 2021 - 08:03:36
Django version 3.2, using settings 'eshop.settings'
Starting development server at http://127.0.0.1:8000/
Quit the server with CTRL-BREAK.
C:\Users\aneeta\Documents\eshop\master\models.py changed, reloading.
Watching for file changes with StatReloader
Exception in thread django-main-thread:
Traceback (most recent call last):
  File "c:\users\aneeta\appdata\local\programs\python\python39\lib\threading.py", line 954, in _bootstrap_inner
    self.run()
  File "c:\users\aneeta\appdata\local\programs\python\python39\lib\threading.py", line 892, in run
    self._target(*self._args, **self._kwargs)
  File "C:\Users\aneeta\Documents\spect_env\lib\site-packages\django\utils\autoreload.py", line 64, in wrapper
    fn(*args, **kwargs)
  File "C:\Users\aneeta\Documents\spect_env\lib\site-packages\django\core\management\commands\runserver.py", line 110, in inner_run
    autoreload.raise_last_exception()
  File "C:\Users\aneeta\Documents\spect_env\lib\site-packages\django\utils\autoreload.py", line 87, in raise_last_exception
    raise _exception[1]
  File "C:\Users\aneeta\Documents\spect_env\lib\site-packages\django\core\management\__init__.py", line 375, in execute
    autoreload.check_errors(django.setup)()
  File "C:\Users\aneeta\Documents\spect_env\lib\site-packages\django\utils\autoreload.py", line 64, in wrapper
    fn(*args, **kwargs)
  File "C:\Users\aneeta\Documents\spect_env\lib\site-packages\django\__init__.py", line 24, in setup
    apps.populate(settings.INSTALLED_APPS)
  File "C:\Users\aneeta\Documents\spect_env\lib\site-packages\django\apps\registry.py", line 114, in populate
    app_config.import_models()
  File "C:\Users\aneeta\Documents\spect_env\lib\site-packages\django\apps\config.py", line 301, in import_models
    self.models_module = import_module(models_module_name)
  File "c:\users\aneeta\appdata\local\programs\python\python39\lib\importlib\__init__.py", line 127, in import_module
    return _bootstrap._gcd_import(name[level:], package, level)
  File "<frozen importlib._bootstrap>", line 1030, in _gcd_import
  File "<frozen importlib._bootstrap>", line 1007, in _find_and_load
  File "<frozen importlib._bootstrap>", line 986, in _find_and_load_unlocked
  File "<frozen importlib._bootstrap>", line 680, in _load_unlocked
  File "<frozen importlib._bootstrap_external>", line 790, in exec_module
  File "<frozen importlib._bootstrap>", line 228, in _call_with_frames_removed
  File "C:\Users\aneeta\Documents\eshop\master\models.py", line 5, in <module>
    class FeedbackModel1(model.Model):
NameError: name 'model' is not defined
C:\Users\aneeta\Documents\eshop\master\models.py changed, reloading.
Watching for file changes with StatReloader
Exception in thread django-main-thread:
Traceback (most recent call last):
  File "c:\users\aneeta\appdata\local\programs\python\python39\lib\threading.py", line 954, in _bootstrap_inner
    self.run()
  File "c:\users\aneeta\appdata\local\programs\python\python39\lib\threading.py", line 892, in run
    self._target(*self._args, **self._kwargs)
  File "C:\Users\aneeta\Documents\spect_env\lib\site-packages\django\utils\autoreload.py", line 64, in wrapper
    fn(*args, **kwargs)
  File "C:\Users\aneeta\Documents\spect_env\lib\site-packages\django\core\management\commands\runserver.py", line 110, in inner_run
    autoreload.raise_last_exception()
  File "C:\Users\aneeta\Documents\spect_env\lib\site-packages\django\utils\autoreload.py", line 87, in raise_last_exception
    raise _exception[1]
  File "C:\Users\aneeta\Documents\spect_env\lib\site-packages\django\core\management\__init__.py", line 375, in execute
    autoreload.check_errors(django.setup)()
  File "C:\Users\aneeta\Documents\spect_env\lib\site-packages\django\utils\autoreload.py", line 64, in wrapper
    fn(*args, **kwargs)
  File "C:\Users\aneeta\Documents\spect_env\lib\site-packages\django\__init__.py", line 24, in setup
    apps.populate(settings.INSTALLED_APPS)
  File "C:\Users\aneeta\Documents\spect_env\lib\site-packages\django\apps\registry.py", line 114, in populate
    app_config.import_models()
  File "C:\Users\aneeta\Documents\spect_env\lib\site-packages\django\apps\config.py", line 301, in import_models
    self.models_module = import_module(models_module_name)
  File "c:\users\aneeta\appdata\local\programs\python\python39\lib\importlib\__init__.py", line 127, in import_module
    return _bootstrap._gcd_import(name[level:], package, level)
  File "<frozen importlib._bootstrap>", line 1030, in _gcd_import
  File "<frozen importlib._bootstrap>", line 1007, in _find_and_load
  File "<frozen importlib._bootstrap>", line 986, in _find_and_load_unlocked
  File "<frozen importlib._bootstrap>", line 680, in _load_unlocked
  File "<frozen importlib._bootstrap_external>", line 790, in exec_module
  File "<frozen importlib._bootstrap>", line 228, in _call_with_frames_removed
  File "C:\Users\aneeta\Documents\eshop\master\models.py", line 5, in <module>
    class FeedbackModel1(model.Model):
NameError: name 'model' is not defined
C:\Users\aneeta\Documents\eshop\master\models.py changed, reloading.
Watching for file changes with StatReloader
Exception in thread django-main-thread:
Traceback (most recent call last):
  File "c:\users\aneeta\appdata\local\programs\python\python39\lib\threading.py", line 954, in _bootstrap_inner
    self.run()
  File "c:\users\aneeta\appdata\local\programs\python\python39\lib\threading.py", line 892, in run
    self._target(*self._args, **self._kwargs)
  File "C:\Users\aneeta\Documents\spect_env\lib\site-packages\django\utils\autoreload.py", line 64, in wrapper
    fn(*args, **kwargs)
  File "C:\Users\aneeta\Documents\spect_env\lib\site-packages\django\core\management\commands\runserver.py", line 110, in inner_run
    autoreload.raise_last_exception()
  File "C:\Users\aneeta\Documents\spect_env\lib\site-packages\django\utils\autoreload.py", line 87, in raise_last_exception
    raise _exception[1]
  File "C:\Users\aneeta\Documents\spect_env\lib\site-packages\django\core\management\__init__.py", line 375, in execute
    autoreload.check_errors(django.setup)()
  File "C:\Users\aneeta\Documents\spect_env\lib\site-packages\django\utils\autoreload.py", line 64, in wrapper
    fn(*args, **kwargs)
  File "C:\Users\aneeta\Documents\spect_env\lib\site-packages\django\__init__.py", line 24, in setup
    apps.populate(settings.INSTALLED_APPS)
  File "C:\Users\aneeta\Documents\spect_env\lib\site-packages\django\apps\registry.py", line 114, in populate
    app_config.import_models()
  File "C:\Users\aneeta\Documents\spect_env\lib\site-packages\django\apps\config.py", line 301, in import_models
    self.models_module = import_module(models_module_name)
  File "c:\users\aneeta\appdata\local\programs\python\python39\lib\importlib\__init__.py", line 127, in import_module
    return _bootstrap._gcd_import(name[level:], package, level)
  File "<frozen importlib._bootstrap>", line 1030, in _gcd_import
  File "<frozen importlib._bootstrap>", line 1007, in _find_and_load
  File "<frozen importlib._bootstrap>", line 986, in _find_and_load_unlocked
  File "<frozen importlib._bootstrap>", line 680, in _load_unlocked
  File "<frozen importlib._bootstrap_external>", line 790, in exec_module
  File "<frozen importlib._bootstrap>", line 228, in _call_with_frames_removed
  File "C:\Users\aneeta\Documents\eshop\master\models.py", line 5, in <module>
    class FeedbackModel1(models.Model):
  File "C:\Users\aneeta\Documents\eshop\master\models.py", line 6, in FeedbackModel1
    name=models.CharField(max_Length=25)
  File "C:\Users\aneeta\Documents\spect_env\lib\site-packages\django\db\models\fields\__init__.py", line 1005, in __init__
    super().__init__(*args, **kwargs)
TypeError: __init__() got an unexpected keyword argument 'max_Length'

(spect_env) C:\Users\aneeta\Documents\eshop>python manage.py runserver
Watching for file changes with StatReloader
Performing system checks...

System check identified no issues (0 silenced).
May 06, 2021 - 08:59:25
Django version 3.2, using settings 'eshop.settings'
Starting development server at http://127.0.0.1:8000/
Quit the server with CTRL-BREAK.

(spect_env) C:\Users\aneeta\Documents\eshop>python manage.py makemigration
Unknown command: 'makemigration'. Did you mean makemigrations?
Type 'manage.py help' for usage.

(spect_env) C:\Users\aneeta\Documents\eshop>python manage.py makemigrations
Migrations for 'master':
  master\migrations\0001_initial.py
    - Create model FeedbackModel1

(spect_env) C:\Users\aneeta\Documents\eshop>python manage.py migrate
Operations to perform:
  Apply all migrations: admin, auth, contenttypes, master, sessions
Running migrations:
  Applying master.0001_initial... OK

(spect_env) C:\Users\aneeta\Documents\eshop>python manage.py makemigrations
You are trying to add a non-nullable field 'place' to feedbackmodel1 without a default; we can't do that (the database needs something to populate existing rows).
Please select a fix:
 1) Provide a one-off default now (will be set on all existing rows with a null value for this column)
 2) Quit, and let me add a default in models.py
Select an option: 1
Please enter the default value now, as valid Python
The datetime and django.utils.timezone modules are available, so you can do e.g. timezone.now
Type 'exit' to exit this prompt
>>> 'kottayam'
Migrations for 'master':
  master\migrations\0002_feedbackmodel1_place.py
    - Add field place to feedbackmodel1

(spect_env) C:\Users\aneeta\Documents\eshop>python manage.py migrate
Operations to perform:
  Apply all migrations: admin, auth, contenttypes, master, sessions
Running migrations:
  Applying master.0002_feedbackmodel1_place... OK

(spect_env) C:\Users\aneeta\Documents\eshop>python manage.py makemigrations
Migrations for 'master':
  master\migrations\0003_auto_20210506_1021.py
    - Alter field contact on feedbackmodel1
    - Alter field place on feedbackmodel1

(spect_env) C:\Users\aneeta\Documents\eshop>python manage.py migrate
Operations to perform:
  Apply all migrations: admin, auth, contenttypes, master, sessions
Running migrations:
  Applying master.0003_auto_20210506_1021... OK

(spect_env) C:\Users\aneeta\Documents\eshop>

